Workbook

Sheet SAP-Auszug
A1: Bilanz/GuV-Position | B1: Text Bilanz/GuV-Position | C1: Summe der Berichtsperiode | D1: Summe der Vergleichsperiode | E1: Absolute Abweichung | F1: Relative Abweichung
C2: Jahr 2025 | D2: Jahr 2024
A3: 1000000 | B3: A k t i v a | C3: 0 | D3: 0 | E3: 0
A4: 1000000 | B4: =========== | C4: 0 | D4: 0 | E4: 0
A5: 1030000 | B5: A. Anlagevermögen | C5: 0 | D5: 0 | E5: 0
A6: 1030000 | B6: ================= | C6: 0 | D6: 0 | E6: 0
A7: 1031000 | B7: I. Immaterielle Vermögensgegenstände | C7: 0 | D7: 0 | E7: 0
A8: 1031000 | B8: =================================== | C8: 0 | D8: 0 | E8: 0
A9: 1031010 | B9: 1. Entgeltlich erworbene Konzessionen, | C9: 0 | D9: 0 | E9: 0
A10: 1031010 | B10: gewerbliche Schutzrechte und ähnliche | C10: 0 | D10: 0 | E10: 0
A11: 1031010 | B11: Rechte und Werte sowie Lizenzen an | C11: 0 | D11: 0 | E11: 0
A12: 1031010 | B12: solchen Rechten und Werten | C12: 0 | D12: 0 | E12: 0
A13: 1031011 | B13: Software und sonstige immaterielle WG | C13: 0 | D13: 0 | E13: 0
A14: 1031011 | B14: ========================================= | C14: 0 | D14: 0 | E14: 0
A15: 1031011 | B15: 050000 Software und sonstige immat. Wirtschaftsgüter | C15: 23331784 | D15: 24007275 | E15: -675491 | F15: 2,8-
A16: 1031011 | B16: Summe Software und sonstige immaterielle WG | C16: 23331784 | D16: 24007275 | E16: -675491 | F16: 2,8-
A17: 1031030 | B17: 2. Geleistete Anzahlungen | C17: 0 | D17: 0 | E17: 0
A18: 1031030 | B18: ===================== | C18: 0 | D18: 0 | E18: 0
A19: 1031031 | B19: 050090 Software Anzahlungen | C19: 61500.77 | D19: 90926.55 | E19: -29425.78 | F19: 32,4-
A20: 1031030 | C20: 61500.77 | D20: 90926.55 | E20: -29425.78 | F20: 32,4-
A21: 1031000 | B21: Summe Immaterielle Vermögensgegenstände | C21: 23393285 | D21: 24098201 | E21: -704916.78 | F21: 2,9-
A22: 1031000 | B22: ======================================= | C22: 0 | D22: 0 | E22: 0
A23: 1032000 | B23: II. Sachanlagen | C23: 0 | D23: 0 | E23: 0
A24: 1032000 | B24: ============ | C24: 0 | D24: 0 | E24: 0
A25: 1032010 | B25: 1. Grundstücke, grundstücksgleiche Rechte und | C25: 0 | D25: 0 | E25: 0
A26: 1032010 | B26: Bauten einschließlich der Bauten auf | C26: 0 | D26: 0 | E26: 0
A27: 1032010 | B27: fremden Grundstücken | C27: 0 | D27: 0 | E27: 0
A28: 1032010 | B28: ====================================== | C28: 0 | D28: 0 | E28: 0
A29: 1032011 | B29: Flughafenbauten (inkl. Grundstücke) | C29: 0 | D29: 0 | E29: 0
A30: 1032011 | B30: 010000 Bauten auf eig.Grundstücken +grundstücksgl.Rechten | C30: 4.6661927e+08 | D30: 4.935888e+08 | E30: -26969527 | F30: 5,5-
A31: 1032011 | C31: 4.6661927e+08 | D31: 4.935888e+08 | E31: -26969527 | F31: 5,5-
A32: 1032012 | B32: Grundstücke mit Wohnbauten | C32: 0 | D32: 0 | E32: 0
A33: 1032012 | B33: 011000 Bebaute Wohngrundstücke (Flank. Massnahmen) | C33: 15893830 | D33: 16219074 | E33: -325244.54 | F33: 2,0-
A34: 1032012 | C34: 15893830 | D34: 16219074 | E34: -325244.54 | F34: 2,0-
A35: 1032013 | B35: Grundstücke ohne Bauten | C35: 0 | D35: 0 | E35: 0
A36: 1032013 | B36: 012000 Grundstücke | C36: 10069325 | D36: 10069325 | E36: 0 | F36: 0,0
A37: 1032013 | C37: 10069325 | D37: 10069325 | E37: 0 | F37: 0,0
A38: 1032014 | B38: Erbbaurechte | C38: 0 | D38: 0 | E38: 0
A39: 1032014 | B39: 013000 Grundstücksgleiche Rechte ohne Bauten | C39: 45422597 | D39: 47633457 | E39: -2210860 | F39: 4,6-
A40: 1032014 | C40: 45422597 | D40: 47633457 | E40: -2210860 | F40: 4,6-
...

Sheet Bilanz
A1: Bilanz zum 31. Dezember 2025
N3: =TODAY() -> 46297
A5: Flughafen Düsseldorf GmbH, Düsseldorf
B9: A K T I V A | F9: 46022 | H9: 45657 | J9: P A S S I V A | N9: 46022 | P9: 45657
F11: EUR | G11: EUR | H11: EUR | N11: EUR | O11: EUR | P11: EUR
B14: A. | C14: ANLAGEVERMÖGEN | J14: A. | K14: EIGENKAPITAL
C16: I. | D16: Immaterielle Vermögensgegenstände | K16: I. | L16: Gezeichnetes Kapital | N16: =+'SAP-Auszug'!C294*-1 -> 25600000 | P16: ='SAP-Auszug'!D294*-1 -> 25600000
K17: II. | L17: Kapitalrücklage | N17: =+'SAP-Auszug'!C298*-1 -> 80582203 | P17: =+'SAP-Auszug'!D298*-1 -> 80582203
D18: 1. | E18: Entgeltlich erworbene Konzessionen, gewerbliche Schutzrechte | K18: III. | L18: Gewinnrücklagen (andere Gewinnrücklagen) | N18: =+'SAP-Auszug'!C304*-1 -> 1230210.1 | P18: =+'SAP-Auszug'!D304*-1 -> 1230210.1
E19: und ähnliche Rechte und Werte sowie Lizenzen an solchen Rechten | K19: IV. | L19: Verlustvortrag | N19: ='SAP-Auszug'!C309*-1 -> -1.4892217e+08 | P19: ='SAP-Auszug'!D309*-1 -> -1.6250925e+08
E20: und Werten | F20: =+'SAP-Auszug'!C16 -> 23331784 | H20: =+'SAP-Auszug'!D16 -> 24007275 | K20: V. | L20: Jahresüberschuss | N20: ='SAP-Auszug'!C1031*-1 -> 20246589 | P20: ='SAP-Auszug'!D1031*-1 -> 13587076
D21: 2. | E21: Geleistete Anzahlungen | F21: =+'SAP-Auszug'!C20 -> 61500.77 | H21: =+'SAP-Auszug'!D20 -> 90926.55 | K21: VI. | L21: Nicht durch Eigenkapital gedeckter Fehlbetrag | N21: ='SAP-Auszug'!C320*-1 -> 21263169 | P21: ='SAP-Auszug'!D320*-1 -> 41509758
G22: =F20+F21 -> 23393285 | H22: =H20+H21 -> 24098201 | O22: =SUM(N16:N21) -> 0 | P22: =SUM(P16:P21) -> 0
J24: B. | K24: SONDERPOSTEN FÜR INVESTITIONSZUSCHÜSSE
K25: ZU SACHANLAGEN | O25: ='SAP-Auszug'!C328*-1 -> 23175339 | P25: ='SAP-Auszug'!D328*-1 -> 25680683
C26: II. | D26: Sachanlagen
D28: 1. | E28: Grundstücke, grundstücksgleiche Rechte und Bauten | J28: C. | K28: SONDERPOSTEN MIT RÜCKLAGEANTEIL | O28: ='SAP-Auszug'!C335*-1 -> 33330800 | P28: ='SAP-Auszug'!D335*-1 -> 35405877
E29: einschließlich der Bauten auf fremden Grundstücken
E30: a) Flughafenbauten inkl. Grundstücke | F30: =+'SAP-Auszug'!C31 -> 4.6661927e+08 | H30: =+'SAP-Auszug'!D31 -> 4.935888e+08
E31: b) Grundstücke mit Wohnbauten | F31: =+'SAP-Auszug'!C34 -> 15893830 | H31: =+'SAP-Auszug'!D34 -> 16219074
E32: c) Grundstücke ohne Bauten | F32: =+'SAP-Auszug'!C37 -> 10069325 | H32: =+'SAP-Auszug'!D37 -> 10069325 | J32: D. | K32: RÜCKSTELLUNGEN
E33: d) Erbbaurechte | F33: =+'SAP-Auszug'!C40 -> 45422597 | H33: =+'SAP-Auszug'!D40 -> 47633457
D34: 2. | E34: Technische Anlagen und Maschinen | K34: 1. | L34: Rückstellungen für Pensionen und ähnliche Verpflichtungen | N34: ='SAP-Auszug'!C344*-1 -> 6926768 | P34: ='SAP-Auszug'!D344*-1 -> 7642053
E35: a) Flughafenanlagen | F35: =+'SAP-Auszug'!C48 -> 162147137 | H35: =+'SAP-Auszug'!D48 -> 152926183 | K35: 2. | L35: Steuerrückstellungen | N35: ='SAP-Auszug'!C349*-1 -> 382170.67 | P35: ='SAP-Auszug'!D349*-1 -> 217165.84
E36: b) Betriebsanlagen | F36: =+'SAP-Auszug'!C51 -> 1.2904117e+08 | H36: =+'SAP-Auszug'!D51 -> 1.328927e+08 | K36: 3. | L36: Sonstige Rückstellungen | N36: ='SAP-Auszug'!C376*-1 -> 53497136 | P36: ='SAP-Auszug'!D376*-1 -> 46057309
D37: 3. | E37: Andere Anlagen, Betriebs- und Geschäftsausstattung | F37: =+'SAP-Auszug'!C59 -> 29725982 | H37: =+'SAP-Auszug'!D59 -> 29227160 | O37: =SUM(N34:N36) -> 60806075 | P37: =SUM(P34:P36) -> 53916527
D38: 4. | E38: Geleistete Anzahlungen und Anlagen im Bau | F38: =+'SAP-Auszug'!C65 -> 1.0669265e+08 | H38: =+'SAP-Auszug'!D65 -> 71983416
G39: =SUM(F30:F38) -> 9.6561197e+08 | H39: =SUM(H30:H38) -> 9.5454011e+08
J40: E. | K40: VERBINDLICHKEITEN
C42: III. | D42: Finanzanlagen | K42: 1. | L42: Verbindlichkeiten gegenüber Kreditinstituten | N42: ='SAP-Auszug'!C404*-1 -> 6.3271334e+08 | P42: ='SAP-Auszug'!D404*-1 -> 7.3868932e+08
K43: 2. | L43: Verbindlichkeiten gegenüber weiteren Darlehensgebern | N43: ='SAP-Auszug'!C412*-1 -> 1.9148117e+08 | P43: ='SAP-Auszug'!D412*-1 -> 123000000
D44: 1. | E44: Anteile an verbundenen Unternehmen | F44: =+'SAP-Auszug'!C76 -> 9508547 | H44: =+'SAP-Auszug'!D76 -> 9508547 | K44: 3. | L44: Verbindlichkeiten aus Lieferungen und Leistungen | N44: ='SAP-Auszug'!C424*-1 -> 9933099 | P44: ='SAP-Auszug'!D424*-1 -> 9374437.6
D45: 2. | E45: Beteiligungen | F45: =+'SAP-Auszug'!C82 -> 2369737.7 | H45: =+'SAP-Auszug'!D82 -> 2369737.7 | K45: 4. | L45: Verbindlichkeiten gegenüber Gesellschaftern | N45: ='SAP-Auszug'!C434*-1 -> 1.3052078e+08 | P45: ='SAP-Auszug'!D434*-1 -> 1.2336988e+08
D46: 3. | E46: Ausleihungen an Unternehmen mit denen ein Beteiligungsverhältnis | K46: 5. | L46: Verbindlichkeiten gegenüber verbundenen Unternehmen | N46: ='SAP-Auszug'!C447*-1 -> 4483686.6 | P46: ='SAP-Auszug'!D447*-1 -> 2681406.4
E47: besteht | F47: =+'SAP-Auszug'!C91 -> 251000 | H47: =+'SAP-Auszug'!D91 -> 878500 | K47: 6. | L47: Verbindlichkeiten gegenüber Unternehmen,
D48: 4. | E48: Sonstige Ausleihungen | F48: =+'SAP-Auszug'!C97 -> 2191.24 | H48: =+'SAP-Auszug'!D97 -> 3960.83 | L48: mit denen ein Beteiligungsverhältnis besteht | N48: ='SAP-Auszug'!C456*-1 -> 1627465.7 | P48: ='SAP-Auszug'!D456*-1 -> 2591912.1
G49: =SUM(F44:F48) -> 12131476 | H49: =SUM(H44:H48) -> 12760746 | K49: 7. | L49: Sonstige Verbindlichkeiten | N49: ='SAP-Auszug'!C505*-1 -> 23022959 | P49: ='SAP-Auszug'!D505*-1 -> 19607182
O50: =SUM(N42:N49) -> 9.937825e+08 | P50: =SUM(P42:P49) -> 1.0193141e+09
G51: =G22+G39+G49 -> 1.0011367e+09 | H51: =H49+H39+H22 -> 9.9139906e+08
B54: B. | C54: UMLAUFVERMÖGEN
...

Sheet G+V
A1: Gewinn- und Verlustrechnung
A3: für den Zeitraum vom 01. Januar bis 31. Dezember 2025
A5: der
A7: Flughafen Düsseldorf GmbH, Düsseldorf
E8: =TODAY() -> 46297
D11: 01.01.-31.12. | E11: 01.01.-31.12.
D12: 2025 | E12: 2024
D14: EUR | E14: EUR
A17: 1. | B17: Umsatzerlöse | D17: ='SAP-Auszug'!C638*-1 -> 4.6722847e+08 | E17: ='SAP-Auszug'!D638*-1 -> 4.4299096e+08
A19: 2. | B19: Andere aktivierte Eigenleistungen | D19: ='SAP-Auszug'!C643*-1 -> 3219669.6 | E19: ='SAP-Auszug'!D643*-1 -> 2047153.4
A21: 3. | B21: Sonstige betriebliche Erträge | D21: ='SAP-Auszug'!C679*-1 -> 11043538 | E21: 10555743
A23: 4. | B23: Materialaufwand
B24: a) | C24: Aufwendungen für Roh-, Hilfs- und Betriebsstoffe | D24: ='SAP-Auszug'!C726 -> 35368094 | E24: ='SAP-Auszug'!D726 -> 32429057
B25: b) | C25: Aufwendungen für bezogene Leistungen | D25: ='SAP-Auszug'!C750 -> 1.215559e+08 | E25: ='SAP-Auszug'!D750 -> 1.2156363e+08
D26: =SUM(D24:D25) -> 1.5692399e+08 | E26: =SUM(E24:E25) -> 1.5399269e+08
A27: 5. | B27: Personalaufwand
B28: a) | C28: Löhne und Gehälter | D28: =+'SAP-Auszug'!C777 -> 94688354 | E28: =+'SAP-Auszug'!D777 -> 88505043
B29: b) | C29: Soziale Abgaben und Aufwendungen für Altersversorgung und für Unterstützung | D29: =+'SAP-Auszug'!C804 -> 25168230 | E29: =+'SAP-Auszug'!D804 -> 23936970
D30: =SUM(D28:D29) -> 1.1985658e+08 | E30: =SUM(E28:E29) -> 1.1244201e+08
A32: 6. | B32: Abschreibungen auf immaterielle Vermögensgegenstände des Anlagevermögens und Sachanlagen | D32: =+'SAP-Auszug'!C825 -> 78541278 | E32: =+'SAP-Auszug'!D825 -> 76329430
A34: 7. | B34: Sonstige betriebliche Aufwendungen | D34: =+'SAP-Auszug'!C941 -> 69384919 | E34: 64915860
A36: 8. | B36: Erträge aus Beteiligungen | D36: =+'SAP-Auszug'!C953*-1 -> 404732.85 | E36: =+'SAP-Auszug'!D953*-1 -> 459341.41
A38: 9. | B38: Erträge aus Gewinnabführungsverträgen | D38: =+'SAP-Auszug'!C957*-1 -> 1193400 | E38: =+'SAP-Auszug'!D957*-1 -> 763751.84
A40: 10. | B40: Erträge aus Ausleihungen des Finanzanlagevermögens | D40: =+'SAP-Auszug'!C964*-1 -> 60270.48 | E40: =+'SAP-Auszug'!D964*-1 -> 145.45
A42: 11. | B42: Sonstige Zinsen und ähnliche Erträge | D42: =+'SAP-Auszug'!C977*-1 -> 1829429.1 | E42: =+'SAP-Auszug'!D977*-1 -> 2803574.2
A44: 12. | B44: Aufwendungen aus Verlustübernahme | D44: =+'SAP-Auszug'!C982 -> 1354804.7 | E44: =+'SAP-Auszug'!D982 -> 1735218.4
A46: 13. | B46: Zinsen und ähnliche Aufwendungen | D46: =+'SAP-Auszug'!C1008 -> 35082809 | E46: =+'SAP-Auszug'!D1008 -> 32906422
A48: 14. | B48: Steuern vom Einkommen und vom Ertrag | D48: =+'SAP-Auszug'!C1018 -> 2867908.9 | E48: =+'SAP-Auszug'!D1018 -> 2020682.5
A50: 15. | B50: Ergebnis nach Steuern | D50: =D17+D19+D21-D24-D25-D28-D29-D32-D34+D36+D38+D40+D42-D44-D46-D48 -> 20967217 | E50: =E17+E19+E21-E24-E25-E28-E29-E32-E34+E36+E38+E40+E42-E44-E46-E48 -> 15278358
A52: 16. | B52: Sonstige Steuern | D52: =+'SAP-Auszug'!C1029 -> 720627.36 | E52: =+'SAP-Auszug'!D1029 -> 1691281.5
A55: 17. | B55: Jahresüberschuss/Jahresfehlbetrag | D55: =D50-D52 -> 20246589 | E55: =E50-E52 -> 13587076
