Workbook

Sheet Mapping
A1: Kundenkonto | B1: Bezeichnung Kunde | C1: Bisheriges YCOA-Konto | D1: Bezeichnung bisheriges YCOA | E1: Bilanzposition Kunde (aus Z) | F1: Bilanzposition bisheriges YCOA (aus Y) | G1: Ergebnis Bezeichnungsprüfung (OK/Abweichung) | H1: Ergebnis Bilanzprüfung (OK/Abweichung/nicht prüfbar) | I1: Neues YCOA-Konto | J1: Bezeichnung neues YCOA | K1: Bilanzposition neues YCOA | L1: Begründung | M1: Konfidenz (hoch/mittel/niedrig) | N1: Status (unverändert/korrigiert/Neuanlage prüfen/manuell klären)
A2: 050000 | B2: Software und sonstige immat. Wirtschaftsgüter | C2: 16020000 | D2: Geringwertige Wirtschaftsgüter | E2: Aktiva > A. Anlagevermögen > I. Immaterielle VG > 1. Konzessionen, Schutzrechte, Lizenzen (Software und sonstige immaterielle WG) [1031011] | F2: Assets > Non-Current Assets > Property Plant & Equipment (Net) > Property Plant & Equipment (Gross) | G2: Abweichung | H2: Abweichung | I2: 19320000 | J2: Intangible Assets | K2: Assets > Non-Current Assets > Other Non-Current Assets > Intangible Assets | L2: Bisher Geringwertige Wirtschaftsgüter (Sachanlagen): weder Sachverhalt noch Bilanzposition passen. Neu Intangible Assets (immaterielle Vermögensgegenstände) in Position Intangible Assets, passend zum Abschreibungskonto 64021000. 1:n beachten: Software kann je Anlagenklasse auf 16008000 Computer Software geführt werden (gleiche Position); kumulierte Abschreibung getrennt auf 19420000 bzw. 17008000 (Kunde weist netto auf einem Konto aus). | M2: mittel | N2: korrigiert
A3: 050090 | B3: Software Anzahlungen | C3: 16012000 | D3: Aktivierte Anzahlungen auf Anlagen | E3: Aktiva > A. Anlagevermögen > I. Immaterielle VG > 2. Geleistete Anzahlungen [1031031] | F3: Assets > Non-Current Assets > Property Plant & Equipment (Net) > Property Plant & Equipment (Gross) | G3: OK | H3: Abweichung | L3: Bezeichnung passt (Anzahlungen auf Anlagen), 16012000 liegt aber in Property Plant & Equipment; der Kunde weist Anzahlungen auf immaterielle VG gesondert unter A.I.2 aus. In Intangible Assets existiert kein Anzahlungskonto. Neuanlage prüfen (Kopiervorlage 16012000, Zuordnung zu Intangible Assets). Rückfall ohne Neuanlage: 16012000 mit abweichendem Bilanzausweis. | M3: hoch | N3: Neuanlage prüfen
A4: 010000 | B4: Bauten auf eig.Grundstücken +grundstücksgl.Rechten | C4: 64000000 | D4: Abschreib. - Grundstücke und grundstücksgl. Rechte | E4: Aktiva > A. Anlagevermögen > II. Sachanlagen > 1. Grundstücke und Bauten > a) Flughafenbauten inkl. Grundstücke [1032011] | F4: nicht in [Y] enthalten | G4: Abweichung | H4: Abweichung | I4: 16001000 | J4: Gebäude / Buildings | K4: Assets > Non-Current Assets > Property Plant & Equipment (Net) > Property Plant & Equipment (Gross) | L4: Bisher Abschreibungskonto (Aufwand, zudem nicht in [Y]) für ein Bestandskonto. Neu Gebäude in Property Plant & Equipment (Gross). Grundstücksanteile je Anlagenklasse auf 16000000. Hinweis: Der Kunde führt Anschaffungskosten und Wertberichtigung auf einem Konto (Nettoausweis); in YCOA sind Bestandskonto (16xxxxxx) und Wertberichtigungskonto (17xxxxxx) getrennt – Kontenfindung FI-AA und Altdatenübernahme brutto je Anlagenklasse. | M4: hoch | N4: korrigiert
A5: 011000 | B5: Bebaute Wohngrundstücke (Flank. Massnahmen) | C5: 17000000 | D5: Wertberichtigungen Grundstücke | E5: Aktiva > A. Anlagevermögen > II. Sachanlagen > 1. Grundstücke und Bauten > b) Grundstücke mit Wohnbauten [1032012] | F5: Assets > Non-Current Assets > Property Plant & Equipment (Net) > Accumulated Depreciation | G5: Abweichung | H5: OK | I5: 16001000 | J5: Gebäude / Buildings | K5: Assets > Non-Current Assets > Property Plant & Equipment (Net) > Property Plant & Equipment (Gross) | L5: Bisher Wertberichtigungskonto (Accumulated Depreciation) für ein Bestandskonto. Neu Gebäude; der Grundstücksanteil der bebauten Wohngrundstücke gehört je Anlagenklasse auf 16000000 (1:n). n:1 mit 010000: die Unterposition b) Grundstücke mit Wohnbauten der Kundenbilanz ist auf Kontenebene nicht mehr trennbar – über Anlagenklasse auswertbar, sonst eigenes Konto anlegen. Hinweis: Der Kunde führt Anschaffungskosten und Wertberichtigung auf einem Konto (Nettoausweis); in YCOA sind Bestandskonto (16xxxxxx) und Wertberichtigungskonto (17xxxxxx) getrennt – Kontenfindung FI-AA und Altdatenübernahme brutto je Anlagenklasse. | M5: mittel | N5: korrigiert
A6: 012000 | B6: Grundstücke | C6: 17000000 | D6: Wertberichtigungen Grundstücke | E6: Aktiva > A. Anlagevermögen > II. Sachanlagen > 1. Grundstücke und Bauten > c) Grundstücke ohne Bauten [1032013] | F6: Assets > Non-Current Assets > Property Plant & Equipment (Net) > Accumulated Depreciation | G6: Abweichung | H6: OK | I6: 16000000 | J6: Grundstücke und grundstücksgleiche Rechte / Land & Land Improvements | K6: Assets > Non-Current Assets > Property Plant & Equipment (Net) > Property Plant & Equipment (Gross) | L6: Bisher Wertberichtigungskonto (Accumulated Depreciation) für ein Bestandskonto. Neu Grundstücke und grundstücksgleiche Rechte in Property Plant & Equipment (Gross). | M6: hoch | N6: korrigiert
A7: 013000 | B7: Grundstücksgleiche Rechte ohne Bauten | C7: 16000000 | D7: Grundstücke und grundstücksgleiche Rechte | E7: Aktiva > A. Anlagevermögen > II. Sachanlagen > 1. Grundstücke und Bauten > d) Erbbaurechte [1032014] | F7: Assets > Non-Current Assets > Property Plant & Equipment (Net) > Property Plant & Equipment (Gross) | G7: OK | H7: OK | I7: 16000000 | J7: Grundstücke und grundstücksgleiche Rechte / Land & Land Improvements | K7: Assets > Non-Current Assets > Property Plant & Equipment (Net) > Property Plant & Equipment (Gross) | L7: Bezeichnung und Bilanzposition passen. n:1 mit 012000: die Unterpositionen c) Grundstücke ohne Bauten und d) Erbbaurechte der Kundenbilanz sind auf Kontenebene nicht mehr trennbar (über Anlagenklasse auswertbar). Hinweis: Der Kunde führt Anschaffungskosten und Wertberichtigung auf einem Konto (Nettoausweis); in YCOA sind Bestandskonto (16xxxxxx) und Wertberichtigungskonto (17xxxxxx) getrennt – Kontenfindung FI-AA und Altdatenübernahme brutto je Anlagenklasse. | M7: hoch | N7: unverändert
A8: 020000 | B8: Außenanlagen / Flughafenanlagen | C8: TBD | E8: Aktiva > A. Anlagevermögen > II. Sachanlagen > 2. Technische Anlagen und Maschinen > a) Flughafenanlagen [1032021] | G8: kein Mapping (TBD) | H8: kein Mapping (TBD) | I8: 16002000 | J8: Machinery & Equipment | K8: Assets > Non-Current Assets > Property Plant & Equipment (Net) > Property Plant & Equipment (Gross) | L8: Bisher ohne Zuordnung. Der Kunde weist Flughafenanlagen unter Technische Anlagen und Maschinen aus; sinngemäß Machinery & Equipment. n:1 mit 030000: die Unterpositionen a) Flughafenanlagen und b) Betriebsanlagen sind auf Kontenebene nicht mehr trennbar – bei Bedarf eigenes Konto anlegen. Hinweis: Der Kunde führt Anschaffungskosten und Wertberichtigung auf einem Konto (Nettoausweis); in YCOA sind Bestandskonto (16xxxxxx) und Wertberichtigungskonto (17xxxxxx) getrennt – Kontenfindung FI-AA und Altdatenübernahme brutto je Anlagenklasse. | M8: mittel | N8: korrigiert
A9: 030000 | B9: Betriebsanlagen | C9: TBD | E9: Aktiva > A. Anlagevermögen > II. Sachanlagen > 2. Technische Anlagen und Maschinen > b) Betriebsanlagen [1032022] | G9: kein Mapping (TBD) | H9: kein Mapping (TBD) | I9: 16002000 | J9: Machinery & Equipment | K9: Assets > Non-Current Assets > Property Plant & Equipment (Net) > Property Plant & Equipment (Gross) | L9: Bisher ohne Zuordnung. Betriebsanlagen entsprechen Technische Anlagen und Maschinen (Machinery & Equipment). n:1 mit 020000 (siehe dort). Hinweis: Der Kunde führt Anschaffungskosten und Wertberichtigung auf einem Konto (Nettoausweis); in YCOA sind Bestandskonto (16xxxxxx) und Wertberichtigungskonto (17xxxxxx) getrennt – Kontenfindung FI-AA und Altdatenübernahme brutto je Anlagenklasse. | M9: hoch | N9: korrigiert
A10: 040000 | B10: Betriebs- und Geschäftsausstattung | C10: 16005000 | D10: Betriebs- und Geschäftsausstattung | E10: Aktiva > A. Anlagevermögen > II. Sachanlagen > 3. Andere Anlagen, Betriebs- und Geschäftsausstattung [1032031] | F10: Assets > Non-Current Assets > Property Plant & Equipment (Net) > Property Plant & Equipment (Gross) | G10: OK | H10: OK | I10: 16005000 | J10: Betriebs- und Geschäftsausstattung / Office Equipment | K10: Assets > Non-Current Assets > Property Plant & Equipment (Net) > Property Plant & Equipment (Gross) | L10: Bezeichnung identisch, Bilanzposition passt. 1:n beachten: Fahrzeuge, Mobiliar, IT-Hardware und geringwertige Wirtschaftsgüter können je Anlagenklasse auf 16004000/16006000/16007000/16020000 differenziert werden. Hinweis: Der Kunde führt Anschaffungskosten und Wertberichtigung auf einem Konto (Nettoausweis); in YCOA sind Bestandskonto (16xxxxxx) und Wertberichtigungskonto (17xxxxxx) getrennt – Kontenfindung FI-AA und Altdatenübernahme brutto je Anlagenklasse. | M10: hoch | N10: unverändert
A11: 058009 | B11: Im Bau befindliche Anlagen + gel. Anzahlungen | C11: 16009000 | D11: Anlagen im Bau | E11: Aktiva > A. Anlagevermögen > II. Sachanlagen > 4. Geleistete Anzahlungen und Anlagen im Bau [1032041] | F11: Assets > Non-Current Assets > Property Plant & Equipment (Net) > Property Plant & Equipment (Gross) | G11: OK | H11: OK | I11: 16009000 | J11: Anlagen im Bau / Assets under Construction | K11: Assets > Non-Current Assets > Property Plant & Equipment (Net) > Property Plant & Equipment (Gross) | L11: Bezeichnung (Anlagen im Bau) und Bilanzposition passen. 1:n beachten: geleistete Anzahlungen auf Sachanlagen laufen in YCOA über 16010000/16012000 (gleiche Position). | M11: hoch | N11: unverändert
A12: 065015 | B12: Beteiligung FD Immobilien GmbH | C12: 18010000 | D12: (in [X] ohne Bezeichnung; laut [Y]: Investment Subsidiaries) | E12: Aktiva > A. Anlagevermögen > III. Finanzanlagen > 1. Anteile an verbundenen Unternehmen [1033010] | F12: Assets > Non-Current Assets > Other Non-Current Assets > Long-Term Investments | G12: OK | H12: OK | I12: 18010000 | J12: Beteiligung Tochtergesellschaften / Investment Subsidiaries | K12: Assets > Non-Current Assets > Other Non-Current Assets > Long-Term Investments | L12: Anteile an verbundenen Unternehmen entsprechen Investment Subsidiaries (Beteiligung Tochtergesellschaften); Position Long-Term Investments passt. In [X] war die Kontonummer ohne Bezeichnung und mit Status TBD hinterlegt – bestätigt. n:1 über vier Gesellschaften: Trennung je Gesellschaft über Partnergesellschaft möglich. | M12: hoch | N12: unverändert
A13: 065016 | B13: Beteiligung FD Ground Handling GmbH | C13: 18010000 | D13: (in [X] ohne Bezeichnung; laut [Y]: Investment Subsidiaries) | E13: Aktiva > A. Anlagevermögen > III. Finanzanlagen > 1. Anteile an verbundenen Unternehmen [1033010] | F13: Assets > Non-Current Assets > Other Non-Current Assets > Long-Term Investments | G13: OK | H13: OK | I13: 18010000 | J13: Beteiligung Tochtergesellschaften / Investment Subsidiaries | K13: Assets > Non-Current Assets > Other Non-Current Assets > Long-Term Investments | L13: Anteile an verbundenen Unternehmen entsprechen Investment Subsidiaries (Beteiligung Tochtergesellschaften); Position Long-Term Investments passt. In [X] war die Kontonummer ohne Bezeichnung und mit Status TBD hinterlegt – bestätigt. n:1 über vier Gesellschaften: Trennung je Gesellschaft über Partnergesellschaft möglich. | M13: hoch | N13: unverändert
A14: 065019 | B14: Beteiligung Flughafen Düsseldorf Security GmbH | C14: 18010000 | D14: (in [X] ohne Bezeichnung; laut [Y]: Investment Subsidiaries) | E14: Aktiva > A. Anlagevermögen > III. Finanzanlagen > 1. Anteile an verbundenen Unternehmen [1033010] | F14: Assets > Non-Current Assets > Other Non-Current Assets > Long-Term Investments | G14: OK | H14: OK | I14: 18010000 | J14: Beteiligung Tochtergesellschaften / Investment Subsidiaries | K14: Assets > Non-Current Assets > Other Non-Current Assets > Long-Term Investments | L14: Anteile an verbundenen Unternehmen entsprechen Investment Subsidiaries (Beteiligung Tochtergesellschaften); Position Long-Term Investments passt. In [X] war die Kontonummer ohne Bezeichnung und mit Status TBD hinterlegt – bestätigt. n:1 über vier Gesellschaften: Trennung je Gesellschaft über Partnergesellschaft möglich. | M14: hoch | N14: unverändert
A15: 065022 | B15: Beteiligung FD Energie GmbH | C15: 18010000 | D15: (in [X] ohne Bezeichnung; laut [Y]: Investment Subsidiaries) | E15: Aktiva > A. Anlagevermögen > III. Finanzanlagen > 1. Anteile an verbundenen Unternehmen [1033010] | F15: Assets > Non-Current Assets > Other Non-Current Assets > Long-Term Investments | G15: OK | H15: OK | I15: 18010000 | J15: Beteiligung Tochtergesellschaften / Investment Subsidiaries | K15: Assets > Non-Current Assets > Other Non-Current Assets > Long-Term Investments | L15: Anteile an verbundenen Unternehmen entsprechen Investment Subsidiaries (Beteiligung Tochtergesellschaften); Position Long-Term Investments passt. In [X] war die Kontonummer ohne Bezeichnung und mit Status TBD hinterlegt – bestätigt. n:1 über vier Gesellschaften: Trennung je Gesellschaft über Partnergesellschaft möglich. | M15: hoch | N15: unverändert
A16: 065018 | B16: Beteiligung SITA Airport IT GmbH | C16: 18010000 | D16: (in [X] ohne Bezeichnung; laut [Y]: Investment Subsidiaries) | E16: Aktiva > A. Anlagevermögen > III. Finanzanlagen > 2. Beteiligungen [1033030/00] | F16: Assets > Non-Current Assets > Other Non-Current Assets > Long-Term Investments | G16: Abweichung | H16: Abweichung | I16: 18020000 | J16: Other Long Term Investments | K16: Assets > Non-Current Assets > Other Non-Current Assets > Long-Term Investments | L16: Beteiligung (Bilanzposition A.III.2 des Kunden), kein verbundenes Unternehmen; 18010000 ist den Tochtergesellschaften vorbehalten, sonst geht die Trennung Anteile an verbundenen Unternehmen / Beteiligungen verloren. Neu Other Long Term Investments (gleiche SAP-Position Long-Term Investments). Bezeichnung des Zielkontos ist generisch; ein eigenes Konto Beteiligungen wäre die saubere Alternative. | M16: mittel | N16: korrigiert
A17: 065025 | B17: Beteiligung Flughafengesell. Mönchengladbach GmbH | C17: 18010000 | D17: (in [X] ohne Bezeichnung; laut [Y]: Investment Subsidiaries) | E17: Aktiva > A. Anlagevermögen > III. Finanzanlagen > 2. Beteiligungen [1033030/00] | F17: Assets > Non-Current Assets > Other Non-Current Assets > Long-Term Investments | G17: Abweichung | H17: Abweichung | I17: 18020000 | J17: Other Long Term Investments | K17: Assets > Non-Current Assets > Other Non-Current Assets > Long-Term Investments | L17: Beteiligung (Bilanzposition A.III.2 des Kunden), kein verbundenes Unternehmen; 18010000 ist den Tochtergesellschaften vorbehalten, sonst geht die Trennung Anteile an verbundenen Unternehmen / Beteiligungen verloren. Neu Other Long Term Investments (gleiche SAP-Position Long-Term Investments). Bezeichnung des Zielkontos ist generisch; ein eigenes Konto Beteiligungen wäre die saubere Alternative. | M17: mittel | N17: korrigiert
A18: 067000 | B18: Beteiligung Swissport DUS Cargo Sevices GmbH | C18: 18010000 | D18: (in [X] ohne Bezeichnung; laut [Y]: Investment Subsidiaries) | E18: Aktiva > A. Anlagevermögen > III. Finanzanlagen > 2. Beteiligungen [1033030/00] | F18: Assets > Non-Current Assets > Other Non-Current Assets > Long-Term Investments | G18: Abweichung | H18: Abweichung | I18: 18020000 | J18: Other Long Term Investments | K18: Assets > Non-Current Assets > Other Non-Current Assets > Long-Term Investments | L18: Beteiligung (Bilanzposition A.III.2 des Kunden), kein verbundenes Unternehmen; 18010000 ist den Tochtergesellschaften vorbehalten, sonst geht die Trennung Anteile an verbundenen Unternehmen / Beteiligungen verloren. Neu Other Long Term Investments (gleiche SAP-Position Long-Term Investments). Bezeichnung des Zielkontos ist generisch; ein eigenes Konto Beteiligungen wäre die saubere Alternative. | M18: mittel | N18: korrigiert
A19: 066002 | B19: Darlehen Flughafen Düsseldorf Cargo GmbH | C19: 19110000 | D19: Sonstige Darlehen - langfristig | E19: Aktiva > A. Anlagevermögen > III. Finanzanlagen > 3. Ausleihungen an Unternehmen mit Beteiligungsverhältnis (Restlaufzeit > 1 Jahr) [1033042] | F19: nicht in [Y] enthalten | G19: OK | H19: Abweichung | L19: Bezeichnung des bisherigen Kontos passt (langfristiges Darlehen), 19110000 ist aber in [Y] nicht vorhanden – Bilanzposition nicht belegbar. In Long-Term Investments gibt es kein Konto für Ausleihungen an Beteiligungsunternehmen (Bilanzposition A.III.3 des Kunden, nach § 266 HGB gesondert auszuweisen). Neuanlage prüfen. Rückfall: 18020000 (Verlust des gesonderten Ausweises) oder 19110000 aus [X] nach Anlage im Buchungskreis und Zuordnung in der Bilanzstruktur. | M19: mittel | N19: Neuanlage prüfen
A20: 064009 | B20: Arbeitgeberdarlehen - Hauptbuchkonto | C20: TBD | E20: Aktiva > A. Anlagevermögen > III. Finanzanlagen > 4. Sonstige Ausleihungen [1033062] | G20: kein Mapping (TBD) | H20: kein Mapping (TBD) | I20: 14107000 | J20: Mitarbeiterdarlehen / Loans to Staff | K20: Assets > Non-Current Assets > Other Non-Current Assets > Long-Term Investments | L20: Bisher ohne Zuordnung. Arbeitgeberdarlehen entsprechen Mitarbeiterdarlehen (Loans to Staff) in Long-Term Investments; Position Sonstige Ausleihungen passt sinngemäß. | M20: hoch | N20: korrigiert
A21: 099200 | B21: Wertberichtigung Altbestand Lagermaterial | C21: 17009000 | D21: Wertberichtigung - Anlagen im Bau | E21: Aktiva > B. Umlaufvermögen > I. Vorräte > 1. Roh-, Hilfs- und Betriebsstoffe [1041010] | F21: Assets > Non-Current Assets > Property Plant & Equipment (Net) > Accumulated Depreciation | G21: Abweichung | H21: Abweichung | I21: 13100900 | J21: Inventory - Revaluation Raw Material | K21: Assets > Current Assets > Inventories | L21: Bisher Wertberichtigung Anlagen im Bau (Anlagevermögen) für eine Wertberichtigung auf Lagermaterial. Neu Inventory - Revaluation Raw Material in Position Inventories (Bewertungsabschlag auf RHB-Bestand). | M21: mittel | N21: korrigiert
A22: 300019 | B22: Material für Kraftfahrzeugwerkstatt | C22: 65200000 | D22: Sonstiges Material | E22: Aktiva > B. Umlaufvermögen > I. Vorräte > 1. Roh-, Hilfs- und Betriebsstoffe [1041010] | F22: Net Income > Operating Income > Operating Expense > Employee Expense > Office Expense | G22: Abweichung | H22: Abweichung | I22: 13100000 | J22: Inventory - Raw Material | K22: Assets > Current Assets > Inventories | L22: Bisher Aufwandskonto Sonstiges Material (Office Expense). Bestandskonto für Lagermaterial: Zielkonto muss in Inventories liegen. Neu Inventory - Raw Material als Bestandskonto für Roh-, Hilfs- und Betriebsstoffe. n:1: die Trennung nach Werkstatt/Materialart geht auf Kontenebene verloren, bleibt aber über Bewertungsklasse, Warengruppe oder Lagerort auswertbar; eigene Bestandskonten je Materialart nur bei Bedarf anlegen. | M22: hoch | N22: korrigiert
A23: 300029 | B23: Material für Klempnerei | C23: 65200000 | D23: Sonstiges Material | E23: Aktiva > B. Umlaufvermögen > I. Vorräte > 1. Roh-, Hilfs- und Betriebsstoffe [1041010] | F23: Net Income > Operating Income > Operating Expense > Employee Expense > Office Expense | G23: Abweichung | H23: Abweichung | I23: 13100000 | J23: Inventory - Raw Material | K23: Assets > Current Assets > Inventories | L23: Bisher Aufwandskonto Sonstiges Material (Office Expense). Bestandskonto für Lagermaterial: Zielkonto muss in Inventories liegen. Neu Inventory - Raw Material als Bestandskonto für Roh-, Hilfs- und Betriebsstoffe. n:1: die Trennung nach Werkstatt/Materialart geht auf Kontenebene verloren, bleibt aber über Bewertungsklasse, Warengruppe oder Lagerort auswertbar; eigene Bestandskonten je Materialart nur bei Bedarf anlegen. | M23: hoch | N23: korrigiert
A24: 300039 | B24: Material für Schreinerei / Schlüsseldienst | C24: 52544000 | D24: Ertr. aus Preisdifferenzen - Material-Ledger (LKW) | E24: Aktiva > B. Umlaufvermögen > I. Vorräte > 1. Roh-, Hilfs- und Betriebsstoffe [1041010] | F24: Net Income > Operating Income > Other Operating Revenue | G24: Abweichung | H24: Abweichung | I24: 13100000 | J24: Inventory - Raw Material | K24: Assets > Current Assets > Inventories | L24: Bisher Ertragskonto Preisdifferenzen Material-Ledger. Bestandskonto für Lagermaterial: Zielkonto muss in Inventories liegen. Neu Inventory - Raw Material als Bestandskonto für Roh-, Hilfs- und Betriebsstoffe. n:1: die Trennung nach Werkstatt/Materialart geht auf Kontenebene verloren, bleibt aber über Bewertungsklasse, Warengruppe oder Lagerort auswertbar; eigene Bestandskonten je Materialart nur bei Bedarf anlegen. | M24: hoch | N24: korrigiert
A25: 300049 | B25: Material für Normteile | C25: 65200000 | D25: Sonstiges Material | E25: Aktiva > B. Umlaufvermögen > I. Vorräte > 1. Roh-, Hilfs- und Betriebsstoffe [1041010] | F25: Net Income > Operating Income > Operating Expense > Employee Expense > Office Expense | G25: Abweichung | H25: Abweichung | I25: 13100000 | J25: Inventory - Raw Material | K25: Assets > Current Assets > Inventories | L25: Bisher Aufwandskonto Sonstiges Material (Office Expense). Bestandskonto für Lagermaterial: Zielkonto muss in Inventories liegen. Neu Inventory - Raw Material als Bestandskonto für Roh-, Hilfs- und Betriebsstoffe. n:1: die Trennung nach Werkstatt/Materialart geht auf Kontenebene verloren, bleibt aber über Bewertungsklasse, Warengruppe oder Lagerort auswertbar; eigene Bestandskonten je Materialart nur bei Bedarf anlegen. | M25: hoch | N25: korrigiert
A26: 300059 | B26: Material für Mechanikerwerkstatt | C26: 65200000 | D26: Sonstiges Material | E26: Aktiva > B. Umlaufvermögen > I. Vorräte > 1. Roh-, Hilfs- und Betriebsstoffe [1041010] | F26: Net Income > Operating Income > Operating Expense > Employee Expense > Office Expense | G26: Abweichung | H26: Abweichung | I26: 13100000 | J26: Inventory - Raw Material | K26: Assets > Current Assets > Inventories | L26: Bisher Aufwandskonto Sonstiges Material (Office Expense). Bestandskonto für Lagermaterial: Zielkonto muss in Inventories liegen. Neu Inventory - Raw Material als Bestandskonto für Roh-, Hilfs- und Betriebsstoffe. n:1: die Trennung nach Werkstatt/Materialart geht auf Kontenebene verloren, bleibt aber über Bewertungsklasse, Warengruppe oder Lagerort auswertbar; eigene Bestandskonten je Materialart nur bei Bedarf anlegen. | M26: hoch | N26: korrigiert
A27: 300069 | B27: Material für Heizungsdienst | C27: 65200000 | D27: Sonstiges Material | E27: Aktiva > B. Umlaufvermögen > I. Vorräte > 1. Roh-, Hilfs- und Betriebsstoffe [1041010] | F27: Net Income > Operating Income > Operating Expense > Employee Expense > Office Expense | G27: Abweichung | H27: Abweichung | I27: 13100000 | J27: Inventory - Raw Material | K27: Assets > Current Assets > Inventories | L27: Bisher Aufwandskonto Sonstiges Material (Office Expense). Bestandskonto für Lagermaterial: Zielkonto muss in Inventories liegen. Neu Inventory - Raw Material als Bestandskonto für Roh-, Hilfs- und Betriebsstoffe. n:1: die Trennung nach Werkstatt/Materialart geht auf Kontenebene verloren, bleibt aber über Bewertungsklasse, Warengruppe oder Lagerort auswertbar; eigene Bestandskonten je Materialart nur bei Bedarf anlegen. | M27: hoch | N27: korrigiert
A28: 300079 | B28: Material für Schlosserei | C28: 65200000 | D28: Sonstiges Material | E28: Aktiva > B. Umlaufvermögen > I. Vorräte > 1. Roh-, Hilfs- und Betriebsstoffe [1041010] | F28: Net Income > Operating Income > Operating Expense > Employee Expense > Office Expense | G28: Abweichung | H28: Abweichung | I28: 13100000 | J28: Inventory - Raw Material | K28: Assets > Current Assets > Inventories | L28: Bisher Aufwandskonto Sonstiges Material (Office Expense). Bestandskonto für Lagermaterial: Zielkonto muss in Inventories liegen. Neu Inventory - Raw Material als Bestandskonto für Roh-, Hilfs- und Betriebsstoffe. n:1: die Trennung nach Werkstatt/Materialart geht auf Kontenebene verloren, bleibt aber über Bewertungsklasse, Warengruppe oder Lagerort auswertbar; eigene Bestandskonten je Materialart nur bei Bedarf anlegen. | M28: hoch | N28: korrigiert
A29: 300089 | B29: Material für Elektrowerkstatt | C29: 65200000 | D29: Sonstiges Material | E29: Aktiva > B. Umlaufvermögen > I. Vorräte > 1. Roh-, Hilfs- und Betriebsstoffe [1041010] | F29: Net Income > Operating Income > Operating Expense > Employee Expense > Office Expense | G29: Abweichung | H29: Abweichung | I29: 13100000 | J29: Inventory - Raw Material | K29: Assets > Current Assets > Inventories | L29: Bisher Aufwandskonto Sonstiges Material (Office Expense). Bestandskonto für Lagermaterial: Zielkonto muss in Inventories liegen. Neu Inventory - Raw Material als Bestandskonto für Roh-, Hilfs- und Betriebsstoffe. n:1: die Trennung nach Werkstatt/Materialart geht auf Kontenebene verloren, bleibt aber über Bewertungsklasse, Warengruppe oder Lagerort auswertbar; eigene Bestandskonten je Materialart nur bei Bedarf anlegen. | M29: hoch | N29: korrigiert
A30: 300099 | B30: Material für Hf-Werkstatt | C30: 50300000 | D30: Kosten des Umsatzes (HF & FE ohne Kostenart) | E30: Aktiva > B. Umlaufvermögen > I. Vorräte > 1. Roh-, Hilfs- und Betriebsstoffe [1041010] | F30: Net Income > Operating Income > Operating Expense > Material Expense | G30: Abweichung | H30: Abweichung | I30: 13100000 | J30: Inventory - Raw Material | K30: Assets > Current Assets > Inventories | L30: Bisher Kosten des Umsatzes (GuV). Bestandskonto für Lagermaterial: Zielkonto muss in Inventories liegen. Neu Inventory - Raw Material als Bestandskonto für Roh-, Hilfs- und Betriebsstoffe. n:1: die Trennung nach Werkstatt/Materialart geht auf Kontenebene verloren, bleibt aber über Bewertungsklasse, Warengruppe oder Lagerort auswertbar; eigene Bestandskonten je Materialart nur bei Bedarf anlegen. | M30: hoch | N30: korrigiert
A31: 673505 | B31: Aufwand Mobilitätssachbezug für MWSt | C31: 66010000 | D31: Aufwand Abzinsung (ZKB) | E31: GuV > 7. Sonstige betriebliche Aufwendungen > Personalnebenkosten [3082034] | F31: Net Income > Operating Income > Operating Expense > Other Operating Expense | G31: Abweichung | H31: Abweichung | I31: 61010000 | J31: Sonstige Personalkosten / Payroll - Other Personnel Expenses | K31: Net Income > Operating Income > Operating Expense > Employee Expense > Payroll and Benefits > Payroll Other | L31: Bisher Aufwand Abzinsung (ZKB): falsch. Aufwand aus Mobilitätssachbezügen als Personalnebenkosten; neu Payroll - Other Personnel Expenses. Umsatzsteuerbezug der Sachbezüge und Gegenkonten 889002/889003 beachten. n:1 auf 61010000 Sonstige Personalkosten – Trennung nach Art der Leistung geht verloren (lohnsteuerliche Behandlung beachten). | M31: mittel | N31: korrigiert
A32: 300119 | B32: Kfz-Betriebsstoffe/Heizstoffe/Öle/Enteisung | C32: TBD | E32: Aktiva > B. Umlaufvermögen > I. Vorräte > 1. Roh-, Hilfs- und Betriebsstoffe [1041010] | G32: kein Mapping (TBD) | H32: kein Mapping (TBD) | I32: 13100000 | J32: Inventory - Raw Material | K32: Assets > Current Assets > Inventories | L32: Bisher ohne Zuordnung. Bestandskonto für Lagermaterial: Zielkonto muss in Inventories liegen. Neu Inventory - Raw Material als Bestandskonto für Roh-, Hilfs- und Betriebsstoffe. n:1: die Trennung nach Werkstatt/Materialart geht auf Kontenebene verloren, bleibt aber über Bewertungsklasse, Warengruppe oder Lagerort auswertbar; eigene Bestandskonten je Materialart nur bei Bedarf anlegen. | M32: hoch | N32: korrigiert
A33: 300139 | B33: Material für Bauabteilung | C33: 65200000 | D33: Sonstiges Material | E33: Aktiva > B. Umlaufvermögen > I. Vorräte > 1. Roh-, Hilfs- und Betriebsstoffe [1041010] | F33: Net Income > Operating Income > Operating Expense > Employee Expense > Office Expense | G33: Abweichung | H33: Abweichung | I33: 13100000 | J33: Inventory - Raw Material | K33: Assets > Current Assets > Inventories | L33: Bisher Aufwandskonto Sonstiges Material (Office Expense). Bestandskonto für Lagermaterial: Zielkonto muss in Inventories liegen. Neu Inventory - Raw Material als Bestandskonto für Roh-, Hilfs- und Betriebsstoffe. n:1: die Trennung nach Werkstatt/Materialart geht auf Kontenebene verloren, bleibt aber über Bewertungsklasse, Warengruppe oder Lagerort auswertbar; eigene Bestandskonten je Materialart nur bei Bedarf anlegen. | M33: hoch | N33: korrigiert
A34: 300149 | B34: Werkzeuge | C34: TBD | E34: Aktiva > B. Umlaufvermögen > I. Vorräte > 1. Roh-, Hilfs- und Betriebsstoffe [1041010] | G34: kein Mapping (TBD) | H34: kein Mapping (TBD) | I34: 13100000 | J34: Inventory - Raw Material | K34: Assets > Current Assets > Inventories | L34: Bisher ohne Zuordnung. Bestandskonto für Lagermaterial: Zielkonto muss in Inventories liegen. Neu Inventory - Raw Material als Bestandskonto für Roh-, Hilfs- und Betriebsstoffe. n:1: die Trennung nach Werkstatt/Materialart geht auf Kontenebene verloren, bleibt aber über Bewertungsklasse, Warengruppe oder Lagerort auswertbar; eigene Bestandskonten je Materialart nur bei Bedarf anlegen. | M34: hoch | N34: korrigiert
A35: 300159 | B35: Berufs-und Schutzkleidung | C35: TBD | E35: Aktiva > B. Umlaufvermögen > I. Vorräte > 1. Roh-, Hilfs- und Betriebsstoffe [1041010] | G35: kein Mapping (TBD) | H35: kein Mapping (TBD) | I35: 13100000 | J35: Inventory - Raw Material | K35: Assets > Current Assets > Inventories | L35: Bisher ohne Zuordnung. Bestandskonto für Lagermaterial: Zielkonto muss in Inventories liegen. Neu Inventory - Raw Material als Bestandskonto für Roh-, Hilfs- und Betriebsstoffe. n:1: die Trennung nach Werkstatt/Materialart geht auf Kontenebene verloren, bleibt aber über Bewertungsklasse, Warengruppe oder Lagerort auswertbar; eigene Bestandskonten je Materialart nur bei Bedarf anlegen. | M35: hoch | N35: korrigiert
A36: 300169 | B36: Material für Malerwerkstatt | C36: 65200000 | D36: Sonstiges Material | E36: Aktiva > B. Umlaufvermögen > I. Vorräte > 1. Roh-, Hilfs- und Betriebsstoffe [1041010] | F36: Net Income > Operating Income > Operating Expense > Employee Expense > Office Expense | G36: Abweichung | H36: Abweichung | I36: 13100000 | J36: Inventory - Raw Material | K36: Assets > Current Assets > Inventories | L36: Bisher Aufwandskonto Sonstiges Material (Office Expense). Bestandskonto für Lagermaterial: Zielkonto muss in Inventories liegen. Neu Inventory - Raw Material als Bestandskonto für Roh-, Hilfs- und Betriebsstoffe. n:1: die Trennung nach Werkstatt/Materialart geht auf Kontenebene verloren, bleibt aber über Bewertungsklasse, Warengruppe oder Lagerort auswertbar; eigene Bestandskonten je Materialart nur bei Bedarf anlegen. | M36: hoch | N36: korrigiert
A37: 300219 | B37: Material - Werbegeschenke < 35 EUR | C37: TBD | E37: Aktiva > B. Umlaufvermögen > I. Vorräte > 1. Roh-, Hilfs- und Betriebsstoffe [1041010] | G37: kein Mapping (TBD) | H37: kein Mapping (TBD) | I37: 13100000 | J37: Inventory - Raw Material | K37: Assets > Current Assets > Inventories | L37: Bisher ohne Zuordnung. Der Kunde führt Werbe- und Jubiläumsgeschenke als Lagerbestand unter RHB. Bestandskonto für Lagermaterial: Zielkonto muss in Inventories liegen. Neu Inventory - Raw Material als Bestandskonto für Roh-, Hilfs- und Betriebsstoffe. n:1: die Trennung nach Werkstatt/Materialart geht auf Kontenebene verloren, bleibt aber über Bewertungsklasse, Warengruppe oder Lagerort auswertbar; eigene Bestandskonten je Materialart nur bei Bedarf anlegen. Für Geschenke ist die steuerliche Trennung auf der Verbrauchsseite relevant (siehe 662xxx). | M37: mittel | N37: korrigiert
A38: 300239 | B38: Heizstoffe | C38: TBD | E38: Aktiva > B. Umlaufvermögen > I. Vorräte > 1. Roh-, Hilfs- und Betriebsstoffe [1041010] | G38: kein Mapping (TBD) | H38: kein Mapping (TBD) | I38: 13100000 | J38: Inventory - Raw Material | K38: Assets > Current Assets > Inventories | L38: Bisher ohne Zuordnung. Bestandskonto für Lagermaterial: Zielkonto muss in Inventories liegen. Neu Inventory - Raw Material als Bestandskonto für Roh-, Hilfs- und Betriebsstoffe. n:1: die Trennung nach Werkstatt/Materialart geht auf Kontenebene verloren, bleibt aber über Bewertungsklasse, Warengruppe oder Lagerort auswertbar; eigene Bestandskonten je Materialart nur bei Bedarf anlegen. | M38: hoch | N38: korrigiert
A39: 300249 | B39: Enteisungsmittel | C39: TBD | E39: Aktiva > B. Umlaufvermögen > I. Vorräte > 1. Roh-, Hilfs- und Betriebsstoffe [1041010] | G39: kein Mapping (TBD) | H39: kein Mapping (TBD) | I39: 13100000 | J39: Inventory - Raw Material | K39: Assets > Current Assets > Inventories | L39: Bisher ohne Zuordnung. Bestandskonto für Lagermaterial: Zielkonto muss in Inventories liegen. Neu Inventory - Raw Material als Bestandskonto für Roh-, Hilfs- und Betriebsstoffe. n:1: die Trennung nach Werkstatt/Materialart geht auf Kontenebene verloren, bleibt aber über Bewertungsklasse, Warengruppe oder Lagerort auswertbar; eigene Bestandskonten je Materialart nur bei Bedarf anlegen. | M39: hoch | N39: korrigiert
A40: 328000 | B40: Werbegeschenke (PR) | C40: TBD | E40: Aktiva > B. Umlaufvermögen > I. Vorräte > 1. Roh-, Hilfs- und Betriebsstoffe [1041010] | G40: kein Mapping (TBD) | H40: kein Mapping (TBD) | I40: 13100000 | J40: Inventory - Raw Material | K40: Assets > Current Assets > Inventories | L40: Bisher ohne Zuordnung. Der Kunde führt Werbe- und Jubiläumsgeschenke als Lagerbestand unter RHB. Bestandskonto für Lagermaterial: Zielkonto muss in Inventories liegen. Neu Inventory - Raw Material als Bestandskonto für Roh-, Hilfs- und Betriebsstoffe. n:1: die Trennung nach Werkstatt/Materialart geht auf Kontenebene verloren, bleibt aber über Bewertungsklasse, Warengruppe oder Lagerort auswertbar; eigene Bestandskonten je Materialart nur bei Bedarf anlegen. Für Geschenke ist die steuerliche Trennung auf der Verbrauchsseite relevant (siehe 662xxx). | M40: mittel | N40: korrigiert
...

Sheet Zusammenfassung
A1: Überarbeitung Kontenplan-Mapping DUS → YCOA: Zusammenfassung
A2: Stand nach den Entscheidungen des Auftraggebers vom 02.10.2026. Alle Kennzahlen sind Formeln auf das Blatt Mapping und rechnen bei Änderungen dort neu.
A4: 1. Kennzahlen
A5: Geprüfte Kundenkonten | B5: =COUNTA(Mapping!$A$2:$A$601) -> 600
A6: davon mit Bilanz-/GuV-Position in [Z] (bilanziell validiert) | B6: =COUNTIF(Mapping!$H$2:$H$601,"<>nicht prüfbar") -> 533
A7: Nicht bilanziell validierte Konten (kein Eintrag in [Z], nur Bezeichnungsprüfung) | B7: =COUNTIF(Mapping!$H$2:$H$601,"nicht prüfbar") -> 67
A8: Korrekturen (Status korrigiert) | B8: =COUNTIF(Mapping!$N$2:$N$601,"korrigiert") -> 359
A9: davon bisher falsch zugeordnet | B9: =COUNTIFS(Mapping!$N$2:$N$601,"korrigiert",Mapping!$C$2:$C$601,"<>TBD") -> 259
A10: davon bisher ohne Zuordnung (TBD), jetzt zugeordnet | B10: =COUNTIFS(Mapping!$N$2:$N$601,"korrigiert",Mapping!$C$2:$C$601,"TBD") -> 100
A11: Unverändert bestätigt | B11: =COUNTIF(Mapping!$N$2:$N$601,"unverändert") -> 95
A12: Neuanlage (entschieden, Vorschlag im Blatt Neuanlagen) | B12: =COUNTIF(Mapping!$N$2:$N$601,"Neuanlage") -> 85
A13: Offene Fälle gesamt (Neuanlage prüfen + manuell klären) | B13: =B14+B15 -> 61
A14: Neuanlage prüfen (kein passendes YCOA-Konto, kein Vorschlag) | B14: =COUNTIF(Mapping!$N$2:$N$601,"Neuanlage prüfen") -> 39
A15: Manuell klären (Sachverhalt oder Ausweis offen) | B15: =COUNTIF(Mapping!$N$2:$N$601,"manuell klären") -> 22
A16: Kontrolle: Summe aller Status = geprüfte Konten | B16: =IF(B8+B11+B12+B14+B15=B5,"OK","Differenz") -> OK
A17: Kontrolle: alle Nummern im Blatt Neuanlagen frei | B17: =IF(COUNTIF(Neuanlagen!$J$6:$J$90,"frei")=B12,"OK","prüfen") -> OK | C17: Vergleich mit den Konten aus [Y] und [X] sowie innerhalb der Liste
A19: 2. Ergebnis der Prüfung des bisherigen Mappings
A20: Bezeichnungsprüfung: OK | B20: =COUNTIF(Mapping!$G$2:$G$601,"OK") -> 136
A21: Bezeichnungsprüfung: Abweichung | B21: =COUNTIF(Mapping!$G$2:$G$601,"Abweichung") -> 314
A22: Bezeichnungsprüfung: kein Mapping (bisher TBD) | B22: =COUNTIF(Mapping!$G$2:$G$601,"kein Mapping (TBD)") -> 150
A23: Bilanzprüfung: OK | B23: =COUNTIF(Mapping!$H$2:$H$601,"OK") -> 148
A24: Bilanzprüfung: Abweichung | B24: =COUNTIF(Mapping!$H$2:$H$601,"Abweichung") -> 251
A25: Bilanzprüfung: kein Mapping (bisher TBD, Konto in [Z]) | B25: =COUNTIF(Mapping!$H$2:$H$601,"kein Mapping (TBD)") -> 134
A26: Bilanzprüfung: nicht prüfbar (Konto nicht in [Z]) | B26: =COUNTIF(Mapping!$H$2:$H$601,"nicht prüfbar") -> 67
A27: Bisheriges Zielkonto in [Y] nicht vorhanden | B27: =COUNTIF(Mapping!$F$2:$F$601,"nicht in [Y] enthalten") -> 56 | C27: Konten aus [X], die im Buchungskreis 10DU / in FPA1 fehlen (u. a. Länderversionen BR/AU)
A28: Bisheriges Zielkonto in FPA1 keiner Position zugeordnet (Not assigned) | B28: =COUNTIF(Mapping!$F$2:$F$601,"Not assigned*") -> 93 | C28: Treasury-, Leasing- (ROU) und Verrechnungskonten außerhalb der Bilanzstruktur
A30: 3. Konfidenz der neuen Einstufung
A31: hoch | B31: =COUNTIF(Mapping!$M$2:$M$601,"hoch") -> 252
A32: mittel | B32: =COUNTIF(Mapping!$M$2:$M$601,"mittel") -> 332
A33: niedrig | B33: =COUNTIF(Mapping!$M$2:$M$601,"niedrig") -> 16
A35: 4. Status nach Bereich
A36: Bereich | B36: unverändert | C36: korrigiert | D36: Neuanlage | E36: Neuanlage prüfen | F36: manuell klären | G36: Summe
A37: Bilanz Aktiva | B37: =COUNTIFS(Mapping!$E$2:$E$601,"Aktiva*",Mapping!$N$2:$N$601,"unverändert") -> 29 | C37: =COUNTIFS(Mapping!$E$2:$E$601,"Aktiva*",Mapping!$N$2:$N$601,"korrigiert") -> 70 | D37: =COUNTIFS(Mapping!$E$2:$E$601,"Aktiva*",Mapping!$N$2:$N$601,"Neuanlage") -> 0 | E37: =COUNTIFS(Mapping!$E$2:$E$601,"Aktiva*",Mapping!$N$2:$N$601,"Neuanlage prüfen") -> 6 | F37: =COUNTIFS(Mapping!$E$2:$E$601,"Aktiva*",Mapping!$N$2:$N$601,"manuell klären") -> 4 | G37: =SUM(B37:F37) -> 109
A38: Bilanz Passiva | B38: =COUNTIFS(Mapping!$E$2:$E$601,"Passiva*",Mapping!$N$2:$N$601,"unverändert") -> 8 | C38: =COUNTIFS(Mapping!$E$2:$E$601,"Passiva*",Mapping!$N$2:$N$601,"korrigiert") -> 50 | D38: =COUNTIFS(Mapping!$E$2:$E$601,"Passiva*",Mapping!$N$2:$N$601,"Neuanlage") -> 0 | E38: =COUNTIFS(Mapping!$E$2:$E$601,"Passiva*",Mapping!$N$2:$N$601,"Neuanlage prüfen") -> 12 | F38: =COUNTIFS(Mapping!$E$2:$E$601,"Passiva*",Mapping!$N$2:$N$601,"manuell klären") -> 3 | G38: =SUM(B38:F38) -> 73
A39: Gewinn- und Verlustrechnung | B39: =COUNTIFS(Mapping!$E$2:$E$601,"GuV*",Mapping!$N$2:$N$601,"unverändert") -> 40 | C39: =COUNTIFS(Mapping!$E$2:$E$601,"GuV*",Mapping!$N$2:$N$601,"korrigiert") -> 181 | D39: =COUNTIFS(Mapping!$E$2:$E$601,"GuV*",Mapping!$N$2:$N$601,"Neuanlage") -> 76 | E39: =COUNTIFS(Mapping!$E$2:$E$601,"GuV*",Mapping!$N$2:$N$601,"Neuanlage prüfen") -> 18 | F39: =COUNTIFS(Mapping!$E$2:$E$601,"GuV*",Mapping!$N$2:$N$601,"manuell klären") -> 8 | G39: =SUM(B39:F39) -> 323
A40: Kalkulatorische Kosten (außerhalb GuV) | B40: =COUNTIFS(Mapping!$E$2:$E$601,"Außerhalb*",Mapping!$N$2:$N$601,"unverändert") -> 10 | C40: =COUNTIFS(Mapping!$E$2:$E$601,"Außerhalb*",Mapping!$N$2:$N$601,"korrigiert") -> 15 | D40: =COUNTIFS(Mapping!$E$2:$E$601,"Außerhalb*",Mapping!$N$2:$N$601,"Neuanlage") -> 0 | E40: =COUNTIFS(Mapping!$E$2:$E$601,"Außerhalb*",Mapping!$N$2:$N$601,"Neuanlage prüfen") -> 1 | F40: =COUNTIFS(Mapping!$E$2:$E$601,"Außerhalb*",Mapping!$N$2:$N$601,"manuell klären") -> 2 | G40: =SUM(B40:F40) -> 28
A41: Nicht in [Z] (nicht bilanziell validiert) | B41: =COUNTIFS(Mapping!$E$2:$E$601,"nicht in*",Mapping!$N$2:$N$601,"unverändert") -> 8 | C41: =COUNTIFS(Mapping!$E$2:$E$601,"nicht in*",Mapping!$N$2:$N$601,"korrigiert") -> 43 | D41: =COUNTIFS(Mapping!$E$2:$E$601,"nicht in*",Mapping!$N$2:$N$601,"Neuanlage") -> 9 | E41: =COUNTIFS(Mapping!$E$2:$E$601,"nicht in*",Mapping!$N$2:$N$601,"Neuanlage prüfen") -> 2 | F41: =COUNTIFS(Mapping!$E$2:$E$601,"nicht in*",Mapping!$N$2:$N$601,"manuell klären") -> 5 | G41: =SUM(B41:F41) -> 67
A42: Summe | B42: =SUM(B37:B41) -> 95 | C42: =SUM(C37:C41) -> 359 | D42: =SUM(D37:D41) -> 85 | E42: =SUM(E37:E41) -> 39 | F42: =SUM(F37:F41) -> 22 | G42: =SUM(G37:G41) -> 600
A43: Konten mit zwei Positionen in [Z] (157300, 195024, 195500) zählen im Bereich der zuerst genannten Position.
A45: 5. Entscheidungen des Auftraggebers vom 02.10.2026
...

Sheet Neuanlagen
A1: Neuanlagen: Vorschlag für die neu anzulegenden Erlöskonten (Entscheidung vom 02.10.2026)
A2: Diese Konten existieren in YCOA noch nicht. Kontonummer = Präfix + Kundenkonto; das Präfix steht in der gelben Eingabezelle C3 und kann geändert werden, die Nummern im Blatt Mapping folgen per Formel. Spalte J prüft die Nummer nur gegen die Konten aus [Y] und [X] (Blatt YCOA-Konten) und auf Dubletten in dieser Liste; vor der Anlage zusätzlich im System gegen den gesamten Kontenplan YCOA prüfen. Bezeichnung = Bezeichnung des Kundenkontos (Langtext, höchstens 50 Zeichen); Kurztexte sind aus dem Altsystem zu übernehmen.
A3: Präfix für neue Kontonummern | C3: 41 | D3: Eingabezelle. Vorschlag 41: Erlösbereich 41xxxxxx, Block 418xxxxx in [Y]/[X] unbelegt; entspricht der im System bereits verwendeten Konvention 99 + Kundenkonto für die kundeneigenen Verrechnungskonten.
A5: Kundenkonto | B5: Bezeichnung Kunde | C5: Neue Kontonummer (Vorschlag) | D5: Bezeichnung neues Konto (Vorschlag, Langtext) | E5: Kopiervorlage (YCOA) | F5: Bezeichnung Kopiervorlage | G5: Vorgesehene Position SAP-Standard (FPA1) | H5: Erlösgruppe / GuV-Zeile Kunde | I5: Saldo 2025 laut [Z] in EUR (Haben negativ) | J5: Prüfung Nummer | K5: Hinweis
A6: 800000 | B6: Grundentgelte | C6: =$C$3&A6 -> 41800000 | D6: Grundentgelte | E6: 41000000 | F6: Erlöse Inland - Erzeugnis / Revenue Domestic - Product | G6: Gross Revenue (FPA1/022) | H6: 1. Umsatzerlöse > Flughafenentgelte > Landeentgelte (fix) | I6: -33107405 | J6: =IF(COUNTIF('YCOA-Konten'!$A$5:$A$708,C6)>0,"belegt",IF(COUNTIF($C$6:$C$90,C6)>1,"doppelt","frei")) -> frei
A7: 800001 | B7: NOX-Entgelte | C7: =$C$3&A7 -> 41800001 | D7: NOX-Entgelte | E7: 41000000 | F7: Erlöse Inland - Erzeugnis / Revenue Domestic - Product | G7: Gross Revenue (FPA1/022) | H7: 1. Umsatzerlöse > Flughafenentgelte > Landeentgelte (fix) | I7: -2527837.5 | J7: =IF(COUNTIF('YCOA-Konten'!$A$5:$A$708,C7)>0,"belegt",IF(COUNTIF($C$6:$C$90,C7)>1,"doppelt","frei")) -> frei
A8: 800002 | B8: Lärmzuschläge | C8: =$C$3&A8 -> 41800002 | D8: Lärmzuschläge | E8: 41000000 | F8: Erlöse Inland - Erzeugnis / Revenue Domestic - Product | G8: Gross Revenue (FPA1/022) | H8: 1. Umsatzerlöse > Flughafenentgelte > Landeentgelte (fix) | I8: -8812148 | J8: =IF(COUNTIF('YCOA-Konten'!$A$5:$A$708,C8)>0,"belegt",IF(COUNTIF($C$6:$C$90,C8)>1,"doppelt","frei")) -> frei
A9: 800010 | B9: Passagierentgelte Inland | C9: =$C$3&A9 -> 41800010 | D9: Passagierentgelte Inland | E9: 41000000 | F9: Erlöse Inland - Erzeugnis / Revenue Domestic - Product | G9: Gross Revenue (FPA1/022) | H9: 1. Umsatzerlöse > Flughafenentgelte > Landeentgelte (variabel) | I9: -13462831 | J9: =IF(COUNTIF('YCOA-Konten'!$A$5:$A$708,C9)>0,"belegt",IF(COUNTIF($C$6:$C$90,C9)>1,"doppelt","frei")) -> frei
A10: 800020 | B10: Lande und Startentg. GAT | C10: =$C$3&A10 -> 41800020 | D10: Lande und Startentg. GAT | E10: 41000000 | F10: Erlöse Inland - Erzeugnis / Revenue Domestic - Product | G10: Gross Revenue (FPA1/022) | H10: 1. Umsatzerlöse > Flughafenentgelte > Landeentgelte (fix) | I10: -1693316.6 | J10: =IF(COUNTIF('YCOA-Konten'!$A$5:$A$708,C10)>0,"belegt",IF(COUNTIF($C$6:$C$90,C10)>1,"doppelt","frei")) -> frei
A11: 800110 | B11: Passagierentgelte NON EU | C11: =$C$3&A11 -> 41800110 | D11: Passagierentgelte NON EU | E11: 41000000 | F11: Erlöse Inland - Erzeugnis / Revenue Domestic - Product | G11: Gross Revenue (FPA1/022) | H11: 1. Umsatzerlöse > Flughafenentgelte > Landeentgelte (variabel) | I11: -71318907 | J11: =IF(COUNTIF('YCOA-Konten'!$A$5:$A$708,C11)>0,"belegt",IF(COUNTIF($C$6:$C$90,C11)>1,"doppelt","frei")) -> frei
A12: 800111 | B12: Passagierentgelte EU | C12: =$C$3&A12 -> 41800111 | D12: Passagierentgelte EU | E12: 41000000 | F12: Erlöse Inland - Erzeugnis / Revenue Domestic - Product | G12: Gross Revenue (FPA1/022) | H12: 1. Umsatzerlöse > Flughafenentgelte > Landeentgelte (variabel) | I12: -94890996 | J12: =IF(COUNTIF('YCOA-Konten'!$A$5:$A$708,C12)>0,"belegt",IF(COUNTIF($C$6:$C$90,C12)>1,"doppelt","frei")) -> frei
A13: 800400 | B13: PRM-Entgelt (People with reduced Mobility) | C13: =$C$3&A13 -> 41800400 | D13: PRM-Entgelt (People with reduced Mobility) | E13: 41000000 | F13: Erlöse Inland - Erzeugnis / Revenue Domestic - Product | G13: Gross Revenue (FPA1/022) | H13: 1. Umsatzerlöse > Flughafenentgelte > Landeentgelte (PRM) | I13: -10936521 | J13: =IF(COUNTIF('YCOA-Konten'!$A$5:$A$708,C13)>0,"belegt",IF(COUNTIF($C$6:$C$90,C13)>1,"doppelt","frei")) -> frei
A14: 800420 | B14: Passagierentgelte Transit / Transfer | C14: =$C$3&A14 -> 41800420 | D14: Passagierentgelte Transit / Transfer | E14: 41000000 | F14: Erlöse Inland - Erzeugnis / Revenue Domestic - Product | G14: Gross Revenue (FPA1/022) | H14: 1. Umsatzerlöse > Flughafenentgelte > Landeentgelte (variabel) | I14: -2220821.8 | J14: =IF(COUNTIF('YCOA-Konten'!$A$5:$A$708,C14)>0,"belegt",IF(COUNTIF($C$6:$C$90,C14)>1,"doppelt","frei")) -> frei
A15: 800430 | B15: EU-Sicherheitsentgelte | C15: =$C$3&A15 -> 41800430 | D15: EU-Sicherheitsentgelte | E15: 41000000 | F15: Erlöse Inland - Erzeugnis / Revenue Domestic - Product | G15: Gross Revenue (FPA1/022) | H15: 1. Umsatzerlöse > Flughafenentgelte > Landeentgelte (variabel) | I15: -14168786 | J15: =IF(COUNTIF('YCOA-Konten'!$A$5:$A$708,C15)>0,"belegt",IF(COUNTIF($C$6:$C$90,C15)>1,"doppelt","frei")) -> frei
A16: 801000 | B16: Abstellentgelte | C16: =$C$3&A16 -> 41801000 | D16: Abstellentgelte | E16: 41000000 | F16: Erlöse Inland - Erzeugnis / Revenue Domestic - Product | G16: Gross Revenue (FPA1/022) | H16: 1. Umsatzerlöse > Flughafenentgelte > Abstellentgelte | I16: -3237343.6 | J16: =IF(COUNTIF('YCOA-Konten'!$A$5:$A$708,C16)>0,"belegt",IF(COUNTIF($C$6:$C$90,C16)>1,"doppelt","frei")) -> frei
A17: 810030 | B17: Zentrale Infrastruktur Counter | C17: =$C$3&A17 -> 41810030 | D17: Zentrale Infrastruktur Counter | E17: 41000000 | F17: Erlöse Inland - Erzeugnis / Revenue Domestic - Product | G17: Gross Revenue (FPA1/022) | H17: 1. Umsatzerlöse > Bodenverkehrsdienste > Abfertigungsentgelte | I17: -5844947.4 | J17: =IF(COUNTIF('YCOA-Konten'!$A$5:$A$708,C17)>0,"belegt",IF(COUNTIF($C$6:$C$90,C17)>1,"doppelt","frei")) -> frei
... A22: 811040 | B22: Sonderleistungen Vorfeldabfertigung | C22: =$C$3&A22 -> 41811040 | D22: Sonderleistungen Vorfeldabfertigung | E22: 41000000 | F22: Erlöse Inland - Erzeugnis / Revenue Domestic - Product | G22: Gross Revenue (FPA1/022) | H22: 1. Umsatzerlöse > Bodenverkehrsdienste > Sonderleistungen | I22: -1067506.7 | J22: =IF(COUNTIF('YCOA-Konten'!$A$5:$A$708,C22)>0,"belegt",IF(COUNTIF($C$6:$C$90,C22)>1,"doppelt","frei")) -> frei
A23: 811090 | B23: Sonderleistungen Enteisung | C23: =$C$3&A23 -> 41811090 | D23: Sonderleistungen Enteisung | E23: 41000000 | F23: Erlöse Inland - Erzeugnis / Revenue Domestic - Product | G23: Gross Revenue (FPA1/022) | H23: 1. Umsatzerlöse > Bodenverkehrsdienste > Sonderleistungen (analog 811xxx, nicht in [Z]) | J23: =IF(COUNTIF('YCOA-Konten'!$A$5:$A$708,C23)>0,"belegt",IF(COUNTIF($C$6:$C$90,C23)>1,"doppelt","frei")) -> frei | K23: Nicht in [Z] (bei FDG 2025/2024 ohne Saldo): Bedarf vor der Anlage bestätigen.
A24: 811110 | B24: Sonderleistungen Gepäckdienst | C24: =$C$3&A24 -> 41811110 | D24: Sonderleistungen Gepäckdienst | E24: 41000000 | F24: Erlöse Inland - Erzeugnis / Revenue Domestic - Product | G24: Gross Revenue (FPA1/022) | H24: 1. Umsatzerlöse > Bodenverkehrsdienste > Sonderleistungen | I24: -27731.27 | J24: =IF(COUNTIF('YCOA-Konten'!$A$5:$A$708,C24)>0,"belegt",IF(COUNTIF($C$6:$C$90,C24)>1,"doppelt","frei")) -> frei
A25: 811120 | B25: Sonderleistungen Personentransporte | C25: =$C$3&A25 -> 41811120 | D25: Sonderleistungen Personentransporte | E25: 41000000 | F25: Erlöse Inland - Erzeugnis / Revenue Domestic - Product | G25: Gross Revenue (FPA1/022) | H25: 1. Umsatzerlöse > Bodenverkehrsdienste > Sonderleistungen (analog 811xxx, nicht in [Z]) | J25: =IF(COUNTIF('YCOA-Konten'!$A$5:$A$708,C25)>0,"belegt",IF(COUNTIF($C$6:$C$90,C25)>1,"doppelt","frei")) -> frei | K25: Nicht in [Z] (bei FDG 2025/2024 ohne Saldo): Bedarf vor der Anlage bestätigen.
A26: 811121 | B26: Sonderleistungen Crew-Transporte | C26: =$C$3&A26 -> 41811121 | D26: Sonderleistungen Crew-Transporte | E26: 41000000 | F26: Erlöse Inland - Erzeugnis / Revenue Domestic - Product | G26: Gross Revenue (FPA1/022) | H26: 1. Umsatzerlöse > Bodenverkehrsdienste > Sonderleistungen (analog 811xxx, nicht in [Z]) | J26: =IF(COUNTIF('YCOA-Konten'!$A$5:$A$708,C26)>0,"belegt",IF(COUNTIF($C$6:$C$90,C26)>1,"doppelt","frei")) -> frei | K26: Nicht in [Z] (bei FDG 2025/2024 ohne Saldo): Bedarf vor der Anlage bestätigen.
A27: 811130 | B27: Containerlagerung | C27: =$C$3&A27 -> 41811130 | D27: Containerlagerung | E27: 41000000 | F27: Erlöse Inland - Erzeugnis / Revenue Domestic - Product | G27: Gross Revenue (FPA1/022) | H27: 1. Umsatzerlöse > Bodenverkehrsdienste > Sonderleistungen | I27: -450628.26 | J27: =IF(COUNTIF('YCOA-Konten'!$A$5:$A$708,C27)>0,"belegt",IF(COUNTIF($C$6:$C$90,C27)>1,"doppelt","frei")) -> frei
A28: 813051 | B28: Nutzungsentgelt FDG-Lounges | C28: =$C$3&A28 -> 41813051 | D28: Nutzungsentgelt FDG-Lounges | E28: 41000000 | F28: Erlöse Inland - Erzeugnis / Revenue Domestic - Product | G28: Gross Revenue (FPA1/022) | H28: 1. Umsatzerlöse > Sonstige Erlöse | I28: -7156311.9 | J28: =IF(COUNTIF('YCOA-Konten'!$A$5:$A$708,C28)>0,"belegt",IF(COUNTIF($C$6:$C$90,C28)>1,"doppelt","frei")) -> frei
A29: 820000 | B29: Mieterlöse Werbung innen | C29: =$C$3&A29 -> 41820000 | D29: Mieterlöse Werbung innen | E29: 41000000 | F29: Erlöse Inland - Erzeugnis / Revenue Domestic - Product | G29: Gross Revenue (FPA1/022) | H29: 1. Umsatzerlöse > Mieterlöse | I29: -1415304.4 | J29: =IF(COUNTIF('YCOA-Konten'!$A$5:$A$708,C29)>0,"belegt",IF(COUNTIF($C$6:$C$90,C29)>1,"doppelt","frei")) -> frei | K29: Bei Vertrags- und Leasingmanagement Kontenfindung auf dieses Konto umstellen (Standard: 70700000).
A30: 820003 | B30: Mieterlöse Werbung | C30: =$C$3&A30 -> 41820003 | D30: Mieterlöse Werbung | E30: 41000000 | F30: Erlöse Inland - Erzeugnis / Revenue Domestic - Product | G30: Gross Revenue (FPA1/022) | H30: 1. Umsatzerlöse > Mieterlöse | I30: -1078826.6 | J30: =IF(COUNTIF('YCOA-Konten'!$A$5:$A$708,C30)>0,"belegt",IF(COUNTIF($C$6:$C$90,C30)>1,"doppelt","frei")) -> frei | K30: Bei Vertrags- und Leasingmanagement Kontenfindung auf dieses Konto umstellen (Standard: 70700000).
A31: 820004 | B31: Dienstleistungen ZI Basisentgelt FDG | C31: =$C$3&A31 -> 41820004 | D31: Dienstleistungen ZI Basisentgelt FDG | E31: 41001500 | F31: Revenue Affiliate - Product | G31: Gross Revenue (FPA1/022) | H31: 1. Umsatzerlöse > Erlösgruppe klären (Nummernkreis der Mieterlöse, Bezeichnung Dienstleistung; nicht in [Z]) | J31: =IF(COUNTIF('YCOA-Konten'!$A$5:$A$708,C31)>0,"belegt",IF(COUNTIF($C$6:$C$90,C31)>1,"doppelt","frei")) -> frei | K31: Erlöse mit verbundenen Unternehmen: Partnergesellschaft mitführen. Nicht in [Z] (bei FDG 2025/2024 ohne Saldo): Bedarf vor der Anlage bestätigen.
A32: 820030 | B32: Mieterlöse Verkaufsgeschäfte | C32: =$C$3&A32 -> 41820030 | D32: Mieterlöse Verkaufsgeschäfte | E32: 41000000 | F32: Erlöse Inland - Erzeugnis / Revenue Domestic - Product | G32: Gross Revenue (FPA1/022) | H32: 1. Umsatzerlöse > Mieterlöse | I32: -231863.81 | J32: =IF(COUNTIF('YCOA-Konten'!$A$5:$A$708,C32)>0,"belegt",IF(COUNTIF($C$6:$C$90,C32)>1,"doppelt","frei")) -> frei | K32: Bei Vertrags- und Leasingmanagement Kontenfindung auf dieses Konto umstellen (Standard: 70700000).
A33: 820031 | B33: Mieterlöse Gastronomie | C33: =$C$3&A33 -> 41820031 | D33: Mieterlöse Gastronomie | E33: 41000000 | F33: Erlöse Inland - Erzeugnis / Revenue Domestic - Product | G33: Gross Revenue (FPA1/022) | H33: 1. Umsatzerlöse > Mieterlöse | I33: -1110992.1 | J33: =IF(COUNTIF('YCOA-Konten'!$A$5:$A$708,C33)>0,"belegt",IF(COUNTIF($C$6:$C$90,C33)>1,"doppelt","frei")) -> frei | K33: Bei Vertrags- und Leasingmanagement Kontenfindung auf dieses Konto umstellen (Standard: 70700000).
A34: 820033 | B34: Mieterlöse Reisemarkt | C34: =$C$3&A34 -> 41820033 | D34: Mieterlöse Reisemarkt | E34: 41000000 | F34: Erlöse Inland - Erzeugnis / Revenue Domestic - Product | G34: Gross Revenue (FPA1/022) | H34: 1. Umsatzerlöse > Mieterlöse | I34: -205955.93 | J34: =IF(COUNTIF('YCOA-Konten'!$A$5:$A$708,C34)>0,"belegt",IF(COUNTIF($C$6:$C$90,C34)>1,"doppelt","frei")) -> frei | K34: Bei Vertrags- und Leasingmanagement Kontenfindung auf dieses Konto umstellen (Standard: 70700000).
A35: 820034 | B35: Mieterlöse DFS/TrValue | C35: =$C$3&A35 -> 41820034 | D35: Mieterlöse DFS/TrValue | E35: 41000000 | F35: Erlöse Inland - Erzeugnis / Revenue Domestic - Product | G35: Gross Revenue (FPA1/022) | H35: 1. Umsatzerlöse > Mieterlöse | I35: -224555.4 | J35: =IF(COUNTIF('YCOA-Konten'!$A$5:$A$708,C35)>0,"belegt",IF(COUNTIF($C$6:$C$90,C35)>1,"doppelt","frei")) -> frei | K35: Bei Vertrags- und Leasingmanagement Kontenfindung auf dieses Konto umstellen (Standard: 70700000).
A36: 820059 | B36: Mieterlöse Sonstiges CO | C36: =$C$3&A36 -> 41820059 | D36: Mieterlöse Sonstiges CO | E36: 41000000 | F36: Erlöse Inland - Erzeugnis / Revenue Domestic - Product | G36: Gross Revenue (FPA1/022) | H36: 1. Umsatzerlöse > Mieterlöse | I36: -245202.02 | J36: =IF(COUNTIF('YCOA-Konten'!$A$5:$A$708,C36)>0,"belegt",IF(COUNTIF($C$6:$C$90,C36)>1,"doppelt","frei")) -> frei | K36: Bei Vertrags- und Leasingmanagement Kontenfindung auf dieses Konto umstellen (Standard: 70700000).
A37: 820060 | B37: Mieterlöse Parken | C37: =$C$3&A37 -> 41820060 | D37: Mieterlöse Parken | E37: 41000000 | F37: Erlöse Inland - Erzeugnis / Revenue Domestic - Product | G37: Gross Revenue (FPA1/022) | H37: 1. Umsatzerlöse > Mieterlöse | I37: -7458709.1 | J37: =IF(COUNTIF('YCOA-Konten'!$A$5:$A$708,C37)>0,"belegt",IF(COUNTIF($C$6:$C$90,C37)>1,"doppelt","frei")) -> frei | K37: Bei Vertrags- und Leasingmanagement Kontenfindung auf dieses Konto umstellen (Standard: 70700000).
A38: 820061 | B38: Mieterlöse Autovermieter | C38: =$C$3&A38 -> 41820061 | D38: Mieterlöse Autovermieter | E38: 41000000 | F38: Erlöse Inland - Erzeugnis / Revenue Domestic - Product | G38: Gross Revenue (FPA1/022) | H38: 1. Umsatzerlöse > Mieterlöse | I38: -6053784.3 | J38: =IF(COUNTIF('YCOA-Konten'!$A$5:$A$708,C38)>0,"belegt",IF(COUNTIF($C$6:$C$90,C38)>1,"doppelt","frei")) -> frei | K38: Bei Vertrags- und Leasingmanagement Kontenfindung auf dieses Konto umstellen (Standard: 70700000).
A39: 820062 | B39: Mieterlöse Catering | C39: =$C$3&A39 -> 41820062 | D39: Mieterlöse Catering | E39: 41000000 | F39: Erlöse Inland - Erzeugnis / Revenue Domestic - Product | G39: Gross Revenue (FPA1/022) | H39: 1. Umsatzerlöse > Mieterlöse | I39: -364634.52 | J39: =IF(COUNTIF('YCOA-Konten'!$A$5:$A$708,C39)>0,"belegt",IF(COUNTIF($C$6:$C$90,C39)>1,"doppelt","frei")) -> frei | K39: Bei Vertrags- und Leasingmanagement Kontenfindung auf dieses Konto umstellen (Standard: 70700000).
A40: 820063 | B40: Mieterlöse Tankdienste | C40: =$C$3&A40 -> 41820063 | D40: Mieterlöse Tankdienste | E40: 41000000 | F40: Erlöse Inland - Erzeugnis / Revenue Domestic - Product | G40: Gross Revenue (FPA1/022) | H40: 1. Umsatzerlöse > Mieterlöse | I40: -594569.34 | J40: =IF(COUNTIF('YCOA-Konten'!$A$5:$A$708,C40)>0,"belegt",IF(COUNTIF($C$6:$C$90,C40)>1,"doppelt","frei")) -> frei | K40: Bei Vertrags- und Leasingmanagement Kontenfindung auf dieses Konto umstellen (Standard: 70700000).
A41: 820064 | B41: Mieterlöse Vermietung | C41: =$C$3&A41 -> 41820064 | D41: Mieterlöse Vermietung | E41: 41000000 | F41: Erlöse Inland - Erzeugnis / Revenue Domestic - Product | G41: Gross Revenue (FPA1/022) | H41: 1. Umsatzerlöse > Mieterlöse | I41: -22865652 | J41: =IF(COUNTIF('YCOA-Konten'!$A$5:$A$708,C41)>0,"belegt",IF(COUNTIF($C$6:$C$90,C41)>1,"doppelt","frei")) -> frei | K41: Bei Vertrags- und Leasingmanagement Kontenfindung auf dieses Konto umstellen (Standard: 70700000).
A42: 820065 | B42: Mieterlöse Lohausen | C42: =$C$3&A42 -> 41820065 | D42: Mieterlöse Lohausen | E42: 41000000 | F42: Erlöse Inland - Erzeugnis / Revenue Domestic - Product | G42: Gross Revenue (FPA1/022) | H42: 1. Umsatzerlöse > Mieterlöse | I42: -985716.79 | J42: =IF(COUNTIF('YCOA-Konten'!$A$5:$A$708,C42)>0,"belegt",IF(COUNTIF($C$6:$C$90,C42)>1,"doppelt","frei")) -> frei | K42: Bei Vertrags- und Leasingmanagement Kontenfindung auf dieses Konto umstellen (Standard: 70700000).
A43: 820067 | B43: Mieterlöse Telekommunikation | C43: =$C$3&A43 -> 41820067 | D43: Mieterlöse Telekommunikation | E43: 41000000 | F43: Erlöse Inland - Erzeugnis / Revenue Domestic - Product | G43: Gross Revenue (FPA1/022) | H43: 1. Umsatzerlöse > Mieterlöse | I43: -928297.77 | J43: =IF(COUNTIF('YCOA-Konten'!$A$5:$A$708,C43)>0,"belegt",IF(COUNTIF($C$6:$C$90,C43)>1,"doppelt","frei")) -> frei | K43: Bei Vertrags- und Leasingmanagement Kontenfindung auf dieses Konto umstellen (Standard: 70700000).
... A47: 823590 | B47: Mieterlöse aus Gebrauchsüberlassung | C47: =$C$3&A47 -> 41823590 | D47: Mieterlöse aus Gebrauchsüberlassung | E47: 41000000 | F47: Erlöse Inland - Erzeugnis / Revenue Domestic - Product | G47: Gross Revenue (FPA1/022) | H47: 1. Umsatzerlöse > Mieterlöse | I47: -2220000 | J47: =IF(COUNTIF('YCOA-Konten'!$A$5:$A$708,C47)>0,"belegt",IF(COUNTIF($C$6:$C$90,C47)>1,"doppelt","frei")) -> frei | K47: Bei Vertrags- und Leasingmanagement Kontenfindung auf dieses Konto umstellen (Standard: 70700000).
A48: 824951 | B48: Mieterlöse Sonstige Grundstücksflächen | C48: =$C$3&A48 -> 41824951 | D48: Mieterlöse Sonstige Grundstücksflächen | E48: 41000000 | F48: Erlöse Inland - Erzeugnis / Revenue Domestic - Product | G48: Gross Revenue (FPA1/022) | H48: 1. Umsatzerlöse > Mieterlöse (analog 820xxx, nicht in [Z]) | J48: =IF(COUNTIF('YCOA-Konten'!$A$5:$A$708,C48)>0,"belegt",IF(COUNTIF($C$6:$C$90,C48)>1,"doppelt","frei")) -> frei | K48: Bei Vertrags- und Leasingmanagement Kontenfindung auf dieses Konto umstellen (Standard: 70700000). Nicht in [Z] (bei FDG 2025/2024 ohne Saldo): Bedarf vor der Anlage bestätigen.
...

Sheet Positionszuordnung
A1: Zuordnung der Bilanz-/GuV-Positionen Kunde [Z] ↔ SAP-Standard [Y] (Bilanzstruktur FPA1)
A2: Grundlage der Bilanzprüfung: ein YCOA-Konto gilt als positionsgleich, wenn seine FPA1-Position zu den hier genannten SAP-Positionen der Kundenposition gehört. Die Strukturen sind unterschiedlich gegliedert (HGB-Gliederung beim Kunden, kostenartenorientierte Standardstruktur in SAP); die Zuordnung erfolgt sinngemäß. Weil die SAP-Positionen gröber sind als die Zeilen der Kundenbilanz/-GuV, gilt zusätzlich: ein YCOA-Konto nimmt nur Kundenkonten derselben Bilanz-/GuV-Zeile auf (siehe Blatt Hinweise).
A4: Bereich | B4: Position Kunde [Z] (Code) | C4: Position Kunde [Z] (Bezeichnung) | D4: Position(en) SAP-Standard [Y] (FPA1) | E4: Art der Zuordnung | F4: Hinweis | G4: Anzahl Kundenkonten
A5: Aktiva | B5: 1031011 | C5: A. Anlagevermögen > I. Immaterielle VG > 1. Konzessionen, Schutzrechte, Lizenzen (Software und sonstige immaterielle WG) | D5: Intangible Assets (FPA1/063); Accumulated Amortization (FPA1/064) | E5: 1:n (verteilt) | F5: Der Nettoausweis des Kunden entspricht Intangible Assets zuzüglich Accumulated Amortization (kumulierte Abschreibungen gesondert). | G5: =COUNTIF(Mapping!$E$2:$E$601,"*["&B5&"*") -> 1
A6: Aktiva | B6: 1031031 | C6: A. Anlagevermögen > I. Immaterielle VG > 2. Geleistete Anzahlungen | D6: Intangible Assets (FPA1/063) | E6: n:1 (zusammengefasst) | F6: In Intangible Assets gibt es kein Anzahlungskonto (Konto 050090: Neuanlage prüfen). | G6: =COUNTIF(Mapping!$E$2:$E$601,"*["&B6&"*") -> 1
